(newenv) [root@cheux171centos7 Python-3.9.19]# python -c "import requests; print(requests.get('https://huggingface.co').status_code)"
Traceback (most recent call last):
  File "/root/newenv/lib/python3.9/site-packages/urllib3/connectionpool.py", line 464, in _make_request
    self._validate_conn(conn)
  File "/root/newenv/lib/python3.9/site-packages/urllib3/connectionpool.py", line 1093, in _validate_conn
    conn.connect()
  File "/root/newenv/lib/python3.9/site-packages/urllib3/connection.py", line 741, in connect
    sock_and_verified = _ssl_wrap_socket_and_match_hostname(
  File "/root/newenv/lib/python3.9/site-packages/urllib3/connection.py", line 920, in _ssl_wrap_socket_and_match_hostname
    ssl_sock = ssl_wrap_socket(
  File "/root/newenv/lib/python3.9/site-packages/urllib3/util/ssl_.py", line 480, in ssl_wrap_socket
    ssl_sock = _ssl_wrap_socket_impl(sock, context, tls_in_tls, server_hostname)
  File "/root/newenv/lib/python3.9/site-packages/urllib3/util/ssl_.py", line 524, in _ssl_wrap_socket_impl
    return ssl_context.wrap_socket(sock, server_hostname=server_hostname)
  File "/usr/local/python3.9.19/lib/python3.9/ssl.py", line 501, in wrap_socket
    return self.sslsocket_class._create(
  File "/usr/local/python3.9.19/lib/python3.9/ssl.py", line 1074, in _create
    self.do_handshake()
  File "/usr/local/python3.9.19/lib/python3.9/ssl.py", line 1343, in do_handshake
    self._sslobj.do_handshake()
ssl.SSLCertVerificationError: [SSL: CERTIFICATE_VERIFY_FAILED] certificate verify failed: unable to get local issuer certificate (_ssl.c:1133)

During handling of the above exception, another exception occurred:

Traceback (most recent call last):
  File "/root/newenv/lib/python3.9/site-packages/urllib3/connectionpool.py", line 787, in urlopen
    response = self._make_request(
  File "/root/newenv/lib/python3.9/site-packages/urllib3/connectionpool.py", line 488, in _make_request
    raise new_e
urllib3.exceptions.SSLError: [SSL: CERTIFICATE_VERIFY_FAILED] certificate verify failed: unable to get local issuer certificate (_ssl.c:1133)

The above exception was the direct cause of the following exception:

Traceback (most recent call last):
  File "/root/newenv/lib/python3.9/site-packages/requests/adapters.py", line 667, in send
    resp = conn.urlopen(
  File "/root/newenv/lib/python3.9/site-packages/urllib3/connectionpool.py", line 841, in urlopen
    retries = retries.increment(
  File "/root/newenv/lib/python3.9/site-packages/urllib3/util/retry.py", line 519, in increment
    raise MaxRetryError(_pool, url, reason) from reason  # type: ignore[arg-type]
urllib3.exceptions.MaxRetryError: HTTPSConnectionPool(host='huggingface.co', port=443): Max retries exceeded with url: / (Caused by SSLError(SSLCertVerificationError(1, '[SSL: CERTIFICATE_VERIFY_FAILED] certificate verify failed: unable to get local issuer certificate (_ssl.c:1133)')))

During handling of the above exception, another exception occurred:

Traceback (most recent call last):
  File "<string>", line 1, in <module>
  File "/root/newenv/lib/python3.9/site-packages/requests/api.py", line 73, in get
    return request("get", url, params=params, **kwargs)
  File "/root/newenv/lib/python3.9/site-packages/requests/api.py", line 59, in request
    return session.request(method=method, url=url, **kwargs)
  File "/root/newenv/lib/python3.9/site-packages/requests/sessions.py", line 589, in request
    resp = self.send(prep, **send_kwargs)
  File "/root/newenv/lib/python3.9/site-packages/requests/sessions.py", line 703, in send
    r = adapter.send(request, **kwargs)
  File "/root/newenv/lib/python3.9/site-packages/requests/adapters.py", line 698, in send
    raise SSLError(e, request=request)
requests.exceptions.SSLError: HTTPSConnectionPool(host='huggingface.co', port=443): Max retries exceeded with url: / (Caused by SSLError(SSLCertVerificationError(1, '[SSL: CERTIFICATE_VERIFY_FAILED] certificate verify failed: unable to get local issuer certificate (_ssl.c:1133)')))
(newenv) [root@cheux171centos7 Python-3.9.19]#
